Workbook

Sheet Guide
A1: VIXIV LTD — Generic flip programme (deal secured → sale completed)
A3: HOW TO USE
A4: 1. Open a Deal tab. Fill the yellow cells: deal name, route (Auction / Estate agent), deal secured date, contractor.
A5: 2. Set the scope switches (Y/N). Activities switched off grey out and take no time; their successors close up automatically.
A6: 3. Replace the default durations (yellow, working days) with your builder's programme once you have it.
A7: 4. Read the Flags column and Key Dates. Hold points (yellow rows) are go/no-go decisions — do not pass them without a decision.
A8: 5. The Pipeline tab compares Deal 1 and Deal 2 and flags if both builds need the crew at the same time.
A9: 6. Update Status as work progresses. To start a new deal, copy a Deal tab (right-click → Move or Copy → Create a copy).
A11: SCHEDULING LOGIC
A12: • All durations are WORKING days (Mon–Fri) and skip every date on the Holidays tab.
A13: • FS = finish-to-start: starts the working day after the predecessor finishes, plus any lag.
A14: • SS = start-to-start: starts with the predecessor, plus the lag in working days.
... A27: Yellow cell + blue text = input you edit. Black = formula. Green text = link from another tab. Red text = flag.

Sheet Pipeline
A1: Pipeline — two overlapping flips
A2: Pulls key dates from Deal 1 and Deal 2. The crew check flags if both builds run at once. To add Deal 3: copy a deal tab and add a column here.
B4: Deal 1 | C4: Deal 2
A5: Deal | B5: ='Deal 1'!$C$5 -> EXAMPLE — 2-bed terrace, Rochdale (replace) | C5: ='Deal 2'!$C$5 -> EXAMPLE — 3-bed semi via agent (replace)
A6: Route | B6: ='Deal 1'!$C$6 -> Auction | C6: ='Deal 2'!$C$6 -> Estate agent
A7: Lead contractor | B7: ='Deal 1'!$C$14 -> Mentor's crew (TBC) | C7: ='Deal 2'!$C$14 -> Friend (general builder)
A8: Deal secured | B8: ='Deal 1'!$C$7 -> 46366 | C8: ='Deal 2'!$C$7 -> 46419
A9: Purchase completion | B9: ='Deal 1'!$I$5 -> 46394 | C9: ='Deal 2'!$I$5 -> 46477
A10: Works start | B10: ='Deal 1'!$I$6 -> 46402 | C10: ='Deal 2'!$I$6 -> 46485
A11: Practical completion | B11: ='Deal 1'!$I$7 -> 46485 | C11: ='Deal 2'!$I$7 -> 46563
A12: Listed | B12: ='Deal 1'!$I$8 -> 46490 | C12: ='Deal 2'!$I$8 -> 46568
A13: Sale completed | B13: ='Deal 1'!$I$10 -> 46605 | C13: ='Deal 2'!$I$10 -> 46682
A14: Months owned | B14: ='Deal 1'!$I$12 -> 6.9316689 | C14: ='Deal 2'!$I$12 -> 6.7345598
A15: Bridge headroom (months) | B15: ='Deal 1'!$I$13 -> 5.0683311 | C15: ='Deal 2'!$I$13 -> 5.2654402
A17: Crew clash check | B17: =IF(AND(B10<C11,C10<B11),"⚠ Builds overlap by "&(MIN(B11,C11)-MAX(B10,C10))&" day(s): confirm a second crew or move Deal 2 later","✓ No build overlap: one crew can run both back-to-back") -> ✓ No build overlap: one crew can run both back-to-back
A18: Capital overlap (both owned at once, days) | B18: =MAX(0,MIN(B13,C13)-MAX(B8,C8)) -> 186 | C18: Days both purchases are funded at the same time — check against the £50k pool.
A21: Phase timeline (weekly) | D21: =TEXT(D22,"mmm yy") -> Dec 26 | E21: =IF(MONTH(E22)<>MONTH(D22),TEXT(E22,"mmm yy"),"") | F21: =IF(MONTH(F22)<>MONTH(E22),TEXT(F22,"mmm yy"),"") | G21: =IF(MONTH(G22)<>MONTH(F22),TEXT(G22,"mmm yy"),"") | H21: =IF(MONTH(H22)<>MONTH(G22),TEXT(H22,"mmm yy"),"") -> Jan 27 | I21: =IF(MONTH(I22)<>MONTH(H22),TEXT(I22,"mmm yy"),"") | J21: =IF(MONTH(J22)<>MONTH(I22),TEXT(J22,"mmm yy"),"") | K21: =IF(MONTH(K22)<>MONTH(J22),TEXT(K22,"mmm yy"),"") | L21: =IF(MONTH(L22)<>MONTH(K22),TEXT(L22,"mmm yy"),"") -> Feb 27 | ... CC21: =IF(MONTH(CC22)<>MONTH(CB22),TEXT(CC22,"mmm yy"),"")
B22: Start | C22: End | D22: =MIN(B8,C8)-WEEKDAY(MIN(B8,C8),3) -> 46363 | E22: =D22+7 -> 46370 | F22: =E22+7 -> 46377 | G22: =F22+7 -> 46384 | H22: =G22+7 -> 46391 | I22: =H22+7 -> 46398 | J22: =I22+7 -> 46405 | K22: =J22+7 -> 46412 | L22: =K22+7 -> 46419 | ... CC22: =CB22+7 -> 46902
A23: Deal 1 — Legal | B23: =B8 -> 46366 | C23: =B9 -> 46394
A24: Deal 1 — Build | B24: =B10 -> 46402 | C24: =B11 -> 46485
A25: Deal 1 — Sale | B25: =B12 -> 46490 | C25: =B13 -> 46605
A26: Deal 2 — Legal | B26: =C8 -> 46419 | C26: =C9 -> 46477
A27: Deal 2 — Build | B27: =C10 -> 46485 | C27: =C11 -> 46563
A28: Deal 2 — Sale | B28: =C12 -> 46568 | C28: =C13 -> 46682

Sheet DD Checklist
A1: Default due-diligence checklist
A2: Stage 1 is done BEFORE bidding (auction) or before the offer is final (agent). Programme ID links each later check to its activity.
A4: # | B4: Stage | C4: Check | D4: Why it matters / what good looks like | E4: Programme ID | F4: Done (Y/N) | G4: Notes
A5: 1 | B5: 1 Before bid / offer | C5: Read the full legal pack with your solicitor | D5: Title, searches, special conditions, completion period, extra fees the buyer pays. | E5: A7
A6: 2 | B6: 1 Before bid / offer | C6: Check special conditions for hidden costs | D6: Seller's legal fees, search fees, arrears, VAT — add all to the appraisal. | E6: —
A7: 3 | B7: 1 Before bid / offer | C7: Why is it at auction / why is it cheap? | D7: Unmortgageable, probate, repossession, structural defect, short lease, sitting tenant. | E7: —
A8: 4 | B8: 1 Before bid / offer | C8: View with the builder; photos and video | D8: Builder's schedule of works and price range before you bid. | E8: B1
A9: 5 | B9: 1 Before bid / offer | C9: Three or more sold comparables (same street/type, last 12 months) | D9: Set the WORST-CASE end value (training rule). | E9: —
A10: 6 | B10: 1 Before bid / offer | C10: DealsDash appraisal: max bid incl. SDLT, fees, buyer's premium | D10: Profit first; stress tests and walk-away tests pass. | E10: —
A11: 7 | B11: 1 Before bid / offer | C11: Construction type and end-buyer mortgageability | D11: Non-standard construction or defects can kill the resale. Your buyer needs a mortgage. | E11: —
A12: 8 | B12: 1 Before bid / offer | C12: Mining, flood, knotweed, conservation area, planning history | D12: Rochdale is a former coalfield: check the Coal Authority report. | E12: —
A13: 9 | B13: 1 Before bid / offer | C13: Tenure and occupancy | D13: Freehold vs leasehold terms; vacant possession confirmed. | E13: —
A14: 10 | B14: 1 Before bid / offer | C14: Bridging decision in principle; lender can complete within 28 days | D14: No DIP = no bid. | E14: A5
A15: 11 | B15: 1 Before bid / offer | C15: Deposit (10%) + fees available on the day; insurance quote ready | D15: Bind insurance at the hammer. | E15: A2
A16: 12 | B16: 1 Before bid / offer | C16: Set the absolute maximum bid and walk away above it | D16: Write it down before the auction starts. | E16: —
... A19: 15 | B19: 2 After deal secured | C19: Contractor contract signed; insurance seen; CIS verified | D19: Fixed price by stage, 5% retention. | E19: B3
A20: 16 | B20: 2 After deal secured | C20: Asbestos survey (pre-2000) before strip-out | E20: B6
A21: 17 | B21: 3 During works | C21: Opening-up review: costs updated in DealsDash | D21: Hidden defects found here; re-check profit. | E21: C2
A22: 18 | B22: 3 During works | C22: First-fix photos before boarding | D22: Proof for certificates and future buyers. | E22: D4
A23: 19 | B23: 4 Before listing | C23: All certificates collected (EIC, Gas Safe, FENSA, Building Control, damp guarantee) | D23: Buyer's solicitor will ask. | E23: G1
A24: 20 | B24: 4 Before listing | C24: EPC commissioned | D24: Must be commissioned before marketing. | E24: G4
A25: 21 | B25: 4 Before listing | C25: Three agent valuations vs your worst-case end value | D25: Price realistically from day one. | E25: H1
A26: 22 | B26: 5 Sale | C26: Sale progression chased weekly | D26: Most delays are paperwork. | E26: H5
A27: 23 | B27: 5 Sale | C27: Bridge redemption statement requested two weeks before completion | D27: No surprise interest or fees. | E27: H7
A28: 24 | B28: 5 Sale | C28: Close-out: actual vs appraised profit and durations | D28: Update this template's default durations. | E28: H9

Sheet Deal 1
A1: VIXIV LTD — Flip programme: Deal 1
A2: Edit only the YELLOW cells (blue text). Dates, Gantt and flags recalculate. Durations are working days. Example values shown — replace with your deal.
B4: DEAL INPUTS | E4: SCOPE SWITCHES (Y/N) | H4: KEY DATES (calculated)
B5: Deal name / address | C5: EXAMPLE — 2-bed terrace, Rochdale (replace) | E5: Pre-2000 build | F5: Y | H5: Purchase completion | I5: =$P$32 -> 46394
B6: Purchase route | C6: Auction | E6: Structural | F6: N | H6: Works start (strip-out) | I6: =$O$40 -> 46402
B7: Deal secured date | C7: 46366 | E7: Damp/timber | F7: Y | H7: Practical completion | I7: =$O$63 -> 46485
B8: Auction completion period (calendar days) | C8: 28 | E8: Roof/external | F8: N | H8: Listed | I8: =$O$67 -> 46490
B9: Agent route: exchange → completion (WD) | C9: 10 | E9: Windows/doors | F9: N | H9: Sale agreed | I9: =$P$68 -> 46533
B10: Contingency on construction durations | C10: 0.15 | E10: Rewire | F10: Y | H10: Sale completed | I10: =$P$72 -> 46605
B11: Winter drying allowance (extra WD, Nov–Feb) | C11: 3 | E11: Heating/boiler | F11: Y | H11: Build duration (WD) | I11: =NETWORKDAYS($I$6,$I$7,Holidays!$B$5:$B$60) -> 58
B12: WD to agree a sale after listing | C12: 30 | E12: Kitchen | F12: Y | H12: Months owned (completion → sale) | I12: =($I$10-$I$5)/30.44 -> 6.9316689
B13: Bridge term (months) | C13: 12 | E13: Bathroom | F13: Y | H13: Bridge headroom (months) | I13: =$C$13-$I$12 -> 5.0683311
B14: Lead contractor | C14: Mentor's crew (TBC) | H14: Deal secured → sale completed (days) | I14: =$I$10-$C$7 -> 239
B15: Sale: exchange → completion (WD) | C15: 10
B17: Gantt key: | C17: A Purchase & DD | D17: B Pre-start | E17: C Strip-out & structure | F17: D First fix | G17: E Plaster | H17: F Second fix & finish | I17: G Sign-off | J17: H Sale & close-out | K17: ■ milestone
U19: =TEXT(U20,"mmm yy") -> Dec 26 | V19: =IF(MONTH(V20)<>MONTH(U20),TEXT(V20,"mmm yy"),"") | W19: =IF(MONTH(W20)<>MONTH(V20),TEXT(W20,"mmm yy"),"") | X19: =IF(MONTH(X20)<>MONTH(W20),TEXT(X20,"mmm yy"),"") | Y19: =IF(MONTH(Y20)<>MONTH(X20),TEXT(Y20,"mmm yy"),"") -> Jan 27 | Z19: =IF(MONTH(Z20)<>MONTH(Y20),TEXT(Z20,"mmm yy"),"") | AA19: =IF(MONTH(AA20)<>MONTH(Z20),TEXT(AA20,"mmm yy"),"") | AB19: =IF(MONTH(AB20)<>MONTH(AA20),TEXT(AB20,"mmm yy"),"") | AC19: =IF(MONTH(AC20)<>MONTH(AB20),TEXT(AC20,"mmm yy"),"") -> Feb 27 | ... CB19: =IF(MONTH(CB20)<>MONTH(CA20),TEXT(CB20,"mmm yy"),"")
A20: ID | B20: Phase | C20: Activity | D20: Owner | E20: Route | F20: Scope switch | G20: Hold point | H20: Dur WD (auction) | I20: Dur WD (agent) | J20: Contingency? | K20: Applies? | L20: Dur used (WD) | M20: Predecessors | N20: Lag (WD) | O20: Start | P20: Finish | Q20: Status | R20: Flags | S20: Notes / what good looks like | U20: =$O$21-WEEKDAY($O$21,3) -> 46363 | V20: =U20+7 -> 46370 | W20: =V20+7 -> 46377 | X20: =W20+7 -> 46384 | Y20: =X20+7 -> 46391 | Z20: =Y20+7 -> 46398 | AA20: =Z20+7 -> 46405 | AB20: =AA20+7 -> 46412 | AC20: =AB20+7 -> 46419 | ... CB20: =CA20+7 -> 46776
A21: A1 | B21: A Purchase & DD | C21: Deal secured (auction: hammer falls = exchange; agent: offer accepted) | D21: Paul | E21: Both | H21: 0 | I21: 0 | J21: N | K21: =IF(AND(OR($E21="Both",$E21=$C$6),OR($F21="",IFERROR(INDEX($F$5:$F$13,MATCH($F21,$E$5:$E$13,0)),"Y")="Y")),"Y","N") -> Y | L21: =IF($K21="N",0,IF(IF($C$6="Auction",$H21,$I21)=0,0,ROUNDUP(IF($C$6="Auction",$H21,$I21)*(1+IF($J21="Y",$C$10,0)),0))) -> 0 | M21: — | N21: 0 | O21: =WORKDAY($C$7-1,1,Holidays!$B$5:$B$60) -> 46366 | P21: =IF($K21="N",WORKDAY($O21,-1,Holidays!$B$5:$B$60),IF($L21=0,$O21,WORKDAY($O21,$L21-1,Holidays!$B$5:$B$60))) -> 46366 | Q21: Not started | R21: =IF(AND($G21="HOLD",$K21="Y"),"■ HOLD: go/no-go. ","") | S21: Day 0. Everything else is driven from the date in C7.
A22: A2 | B22: A Purchase & DD | C22: Buildings insurance (unoccupied cover) in force | D22: Paul / broker | E22: Both | H22: 1 | I22: 1 | J22: N | K22: =IF(AND(OR($E22="Both",$E22=$C$6),OR($F22="",IFERROR(INDEX($F$5:$F$13,MATCH($F22,$E$5:$E$13,0)),"Y")="Y")),"Y","N") -> Y | L22: =IF($K22="N",0,IF(IF($C$6="Auction",$H22,$I22)=0,0,ROUNDUP(IF($C$6="Auction",$H22,$I22)*(1+IF($J22="Y",$C$10,0)),0))) -> 1 | M22: A1SS | N22: 0 | O22: =WORKDAY($O$21,$N22,Holidays!$B$5:$B$60) -> 46366 | P22: =IF($K22="N",WORKDAY($O22,-1,Holidays!$B$5:$B$60),IF($L22=0,$O22,WORKDAY($O22,$L22-1,Holidays!$B$5:$B$60))) -> 46366 | Q22: Not started | R22: =IF(AND($G22="HOLD",$K22="Y"),"■ HOLD: go/no-go. ","") | S22: Auction: risk passes to you at the hammer. Agent route: must be on cover from exchange at the latest.
A23: A3 | B23: A Purchase & DD | C23: Pay 10% deposit + buyer's premium / auction fees | D23: Paul | E23: Auction | H23: 1 | I23: 0 | J23: N | K23: =IF(AND(OR($E23="Both",$E23=$C$6),OR($F23="",IFERROR(INDEX($F$5:$F$13,MATCH($F23,$E$5:$E$13,0)),"Y")="Y")),"Y","N") -> Y | L23: =IF($K23="N",0,IF(IF($C$6="Auction",$H23,$I23)=0,0,ROUNDUP(IF($C$6="Auction",$H23,$I23)*(1+IF($J23="Y",$C$10,0)),0))) -> 1 | M23: A1SS | N23: 0 | O23: =WORKDAY($O$21,$N23,Holidays!$B$5:$B$60) -> 46366 | P23: =IF($K23="N",WORKDAY($O23,-1,Holidays!$B$5:$B$60),IF($L23=0,$O23,WORKDAY($O23,$L23-1,Holidays!$B$5:$B$60))) -> 46366 | Q23: Not started | R23: =IF(AND($G23="HOLD",$K23="Y"),"■ HOLD: go/no-go. ","") | S23: Paid on the day. Funds must be ready before you bid.
A24: A4 | B24: A Purchase & DD | C24: Instruct solicitor; legal pack / memorandum of sale to solicitor and lender | D24: Paul | E24: Both | H24: 2 | I24: 2 | J24: N | K24: =IF(AND(OR($E24="Both",$E24=$C$6),OR($F24="",IFERROR(INDEX($F$5:$F$13,MATCH($F24,$E$5:$E$13,0)),"Y")="Y")),"Y","N") -> Y | L24: =IF($K24="N",0,IF(IF($C$6="Auction",$H24,$I24)=0,0,ROUNDUP(IF($C$6="Auction",$H24,$I24)*(1+IF($J24="Y",$C$10,0)),0))) -> 2 | M24: A1SS | N24: 0 | O24: =WORKDAY($O$21,$N24,Holidays!$B$5:$B$60) -> 46366 | P24: =IF($K24="N",WORKDAY($O24,-1,Holidays!$B$5:$B$60),IF($L24=0,$O24,WORKDAY($O24,$L24-1,Holidays!$B$5:$B$60))) -> 46367 | Q24: Not started | R24: =IF(AND($G24="HOLD",$K24="Y"),"■ HOLD: go/no-go. ","")
A25: A5 | B25: A Purchase & DD | C25: Bridging valuation instructed and inspection done | D25: Broker / lender | E25: Both | H25: 5 | I25: 5 | J25: N | K25: =IF(AND(OR($E25="Both",$E25=$C$6),OR($F25="",IFERROR(INDEX($F$5:$F$13,MATCH($F25,$E$5:$E$13,0)),"Y")="Y")),"Y","N") -> Y | L25: =IF($K25="N",0,IF(IF($C$6="Auction",$H25,$I25)=0,0,ROUNDUP(IF($C$6="Auction",$H25,$I25)*(1+IF($J25="Y",$C$10,0)),0))) -> 5 | M25: A4SS | N25: 1 | O25: =WORKDAY($O$24,$N25,Holidays!$B$5:$B$60) -> 46367 | P25: =IF($K25="N",WORKDAY($O25,-1,Holidays!$B$5:$B$60),IF($L25=0,$O25,WORKDAY($O25,$L25-1,Holidays!$B$5:$B$60))) -> 46373 | Q25: Not started | R25: =IF(AND($G25="HOLD",$K25="Y"),"■ HOLD: go/no-go. ","") | S25: Ideally have a decision in principle BEFORE the auction.
A26: A6 | B26: A Purchase & DD | C26: Bridging underwriting and formal loan offer | D26: Lender | E26: Both | H26: 5 | I26: 5 | J26: N | K26: =IF(AND(OR($E26="Both",$E26=$C$6),OR($F26="",IFERROR(INDEX($F$5:$F$13,MATCH($F26,$E$5:$E$13,0)),"Y")="Y")),"Y","N") -> Y | L26: =IF($K26="N",0,IF(IF($C$6="Auction",$H26,$I26)=0,0,ROUNDUP(IF($C$6="Auction",$H26,$I26)*(1+IF($J26="Y",$C$10,0)),0))) -> 5 | M26: A5FS | N26: 0 | O26: =WORKDAY($P$25,1+$N26,Holidays!$B$5:$B$60) -> 46374 | P26: =IF($K26="N",WORKDAY($O26,-1,Holidays!$B$5:$B$60),IF($L26=0,$O26,WORKDAY($O26,$L26-1,Holidays!$B$5:$B$60))) -> 46380 | Q26: Not started | R26: =IF(AND($G26="HOLD",$K26="Y"),"■ HOLD: go/no-go. ","")
A27: A7 | B27: A Purchase & DD | C27: Searches and enquiries raised and answered | D27: Solicitor | E27: Estate agent | H27: 0 | I27: 25 | J27: N | K27: =IF(AND(OR($E27="Both",$E27=$C$6),OR($F27="",IFERROR(INDEX($F$5:$F$13,MATCH($F27,$E$5:$E$13,0)),"Y")="Y")),"Y","N") -> N | L27: =IF($K27="N",0,IF(IF($C$6="Auction",$H27,$I27)=0,0,ROUNDUP(IF($C$6="Auction",$H27,$I27)*(1+IF($J27="Y",$C$10,0)),0))) -> 0 | M27: A4FS | N27: 0 | O27: =WORKDAY($P$24,1+$N27,Holidays!$B$5:$B$60) -> 46370 | P27: =IF($K27="N",WORKDAY($O27,-1,Holidays!$B$5:$B$60),IF($L27=0,$O27,WORKDAY($O27,$L27-1,Holidays!$B$5:$B$60))) -> 46367 | Q27: Not started | R27: =IF(AND($G27="HOLD",$K27="Y"),"■ HOLD: go/no-go. ","") | S27: Auction route: done BEFORE bidding (see DD Checklist).
A28: A8 | B28: A Purchase & DD | C28: Independent survey + builder walk-round for quote | D28: Surveyor / builder | E28: Estate agent | H28: 0 | I28: 10 | J28: N | K28: =IF(AND(OR($E28="Both",$E28=$C$6),OR($F28="",IFERROR(INDEX($F$5:$F$13,MATCH($F28,$E$5:$E$13,0)),"Y")="Y")),"Y","N") -> N | L28: =IF($K28="N",0,IF(IF($C$6="Auction",$H28,$I28)=0,0,ROUNDUP(IF($C$6="Auction",$H28,$I28)*(1+IF($J28="Y",$C$10,0)),0))) -> 0 | M28: A4SS | N28: 2 | O28: =WORKDAY($O$24,$N28,Holidays!$B$5:$B$60) -> 46370 | P28: =IF($K28="N",WORKDAY($O28,-1,Holidays!$B$5:$B$60),IF($L28=0,$O28,WORKDAY($O28,$L28-1,Holidays!$B$5:$B$60))) -> 46367 | Q28: Not started | R28: =IF(AND($G28="HOLD",$K28="Y"),"■ HOLD: go/no-go. ","")
A29: A9 | B29: A Purchase & DD | C29: Review title, searches and survey: renegotiate or withdraw | D29: Paul + mentor | E29: Estate agent | G29: HOLD | H29: 0 | I29: 3 | J29: N | K29: =IF(AND(OR($E29="Both",$E29=$C$6),OR($F29="",IFERROR(INDEX($F$5:$F$13,MATCH($F29,$E$5:$E$13,0)),"Y")="Y")),"Y","N") -> N | L29: =IF($K29="N",0,IF(IF($C$6="Auction",$H29,$I29)=0,0,ROUNDUP(IF($C$6="Auction",$H29,$I29)*(1+IF($J29="Y",$C$10,0)),0))) -> 0 | M29: A7FS; A8FS | N29: 0 | O29: =MAX(WORKDAY($P$27,1+$N29,Holidays!$B$5:$B$60),WORKDAY($P$28,1+$N29,Holidays!$B$5:$B$60)) -> 46370 | P29: =IF($K29="N",WORKDAY($O29,-1,Holidays!$B$5:$B$60),IF($L29=0,$O29,WORKDAY($O29,$L29-1,Holidays!$B$5:$B$60))) -> 46367 | Q29: Not started | R29: =IF(AND($G29="HOLD",$K29="Y"),"■ HOLD: go/no-go. ","") | S29: Re-run the DealsDash appraisal with real costs. Walk away if it fails.
A30: A10 | B30: A Purchase & DD | C30: Exchange contracts (deposit paid) | D30: Solicitor | E30: Estate agent | H30: 0 | I30: 0 | J30: N | K30: =IF(AND(OR($E30="Both",$E30=$C$6),OR($F30="",IFERROR(INDEX($F$5:$F$13,MATCH($F30,$E$5:$E$13,0)),"Y")="Y")),"Y","N") -> N | L30: =IF($K30="N",0,IF(IF($C$6="Auction",$H30,$I30)=0,0,ROUNDUP(IF($C$6="Auction",$H30,$I30)*(1+IF($J30="Y",$C$10,0)),0))) -> 0 | M30: A9FS; A6FS | N30: 0 | O30: =MAX(WORKDAY($P$29,1+$N30,Holidays!$B$5:$B$60),WORKDAY($P$26,1+$N30,Holidays!$B$5:$B$60)) -> 46391 | P30: =IF($K30="N",WORKDAY($O30,-1,Holidays!$B$5:$B$60),IF($L30=0,$O30,WORKDAY($O30,$L30-1,Holidays!$B$5:$B$60))) -> 46380 | Q30: Not started | R30: =IF(AND($G30="HOLD",$K30="Y"),"■ HOLD: go/no-go. ","") | S30: Legally committed from here.
A31: A11 | B31: A Purchase & DD | C31: Lender's legal work, report on title, funds requested | D31: Solicitors | E31: Both | H31: 5 | I31: 5 | J31: N | K31: =IF(AND(OR($E31="Both",$E31=$C$6),OR($F31="",IFERROR(INDEX($F$5:$F$13,MATCH($F31,$E$5:$E$13,0)),"Y")="Y")),"Y","N") -> Y | L31: =IF($K31="N",0,IF(IF($C$6="Auction",$H31,$I31)=0,0,ROUNDUP(IF($C$6="Auction",$H31,$I31)*(1+IF($J31="Y",$C$10,0)),0))) -> 5 | M31: A6FS; A10FS | N31: 0 | O31: =MAX(WORKDAY($P$26,1+$N31,Holidays!$B$5:$B$60),WORKDAY($P$30,1+$N31,Holidays!$B$5:$B$60)) -> 46391 | P31: =IF($K31="N",WORKDAY($O31,-1,Holidays!$B$5:$B$60),IF($L31=0,$O31,WORKDAY($O31,$L31-1,Holidays!$B$5:$B$60))) -> 46395 | Q31: Not started | R31: =IF(AND($G31="HOLD",$K31="Y"),"■ HOLD: go/no-go. ","")
A32: A12 | B32: A Purchase & DD | C32: PURCHASE COMPLETION: keys released | D32: Solicitor | E32: Both | H32: 0 | I32: 0 | J32: N | K32: =IF(AND(OR($E32="Both",$E32=$C$6),OR($F32="",IFERROR(INDEX($F$5:$F$13,MATCH($F32,$E$5:$E$13,0)),"Y")="Y")),"Y","N") -> Y | L32: =IF($K32="N",0,IF(IF($C$6="Auction",$H32,$I32)=0,0,ROUNDUP(IF($C$6="Auction",$H32,$I32)*(1+IF($J32="Y",$C$10,0)),0))) -> 0 | M32: A1 (auction) / A10, A11 (agent) | N32: 0 | O32: =IF($C$6="Auction",WORKDAY($O$21+$C$8-1,1,Holidays!$B$5:$B$60),MAX(WORKDAY($P$30,$C$9,Holidays!$B$5:$B$60),WORKDAY($P$31,1,Holidays!$B$5:$B$60))) -> 46394 | P32: =IF($K32="N",WORKDAY($O32,-1,Holidays!$B$5:$B$60),IF($L32=0,$O32,WORKDAY($O32,$L32-1,Holidays!$B$5:$B$60))) -> 46394 | Q32: Not started | R32: =IF(AND($G32="HOLD",$K32="Y"),"■ HOLD: go/no-go. ","")&IF(AND($C$6="Auction",$P$31>$O32),"⚠ Finance not ready by auction completion: deposit at risk. ","") -> ⚠ Finance not ready by auction completion: deposit at risk. | S32: Auction: fixed by contract (usually 28 calendar days). Agent: exchange + C9 working days.
A33: B1 | B33: B Pre-start | C33: Builder schedule of works and measured scope | D33: Builder | E33: Both | H33: 3 | I33: 3 | J33: N | K33: =IF(AND(OR($E33="Both",$E33=$C$6),OR($F33="",IFERROR(INDEX($F$5:$F$13,MATCH($F33,$E$5:$E$13,0)),"Y")="Y")),"Y","N") -> Y | L33: =IF($K33="N",0,IF(IF($C$6="Auction",$H33,$I33)=0,0,ROUNDUP(IF($C$6="Auction",$H33,$I33)*(1+IF($J33="Y",$C$10,0)),0))) -> 3 | M33: A1FS; A8FS | N33: 0 | O33: =MAX(WORKDAY($P$21,1+$N33,Holidays!$B$5:$B$60),WORKDAY($P$28,1+$N33,Holidays!$B$5:$B$60)) -> 46370 | P33: =IF($K33="N",WORKDAY($O33,-1,Holidays!$B$5:$B$60),IF($L33=0,$O33,WORKDAY($O33,$L33-1,Holidays!$B$5:$B$60))) -> 46372 | Q33: Not started | R33: =IF(AND($G33="HOLD",$K33="Y"),"■ HOLD: go/no-go. ","") | S33: Auction: arrange access via auctioneer/seller, or use the pre-bid viewing scope.
A34: B2 | B34: B Pre-start | C34: Fixed-price quote(s) received; mentor review | D34: Builder / mentor | E34: Both | H34: 5 | I34: 5 | J34: N | K34: =IF(AND(OR($E34="Both",$E34=$C$6),OR($F34="",IFERROR(INDEX($F$5:$F$13,MATCH($F34,$E$5:$E$13,0)),"Y")="Y")),"Y","N") -> Y | L34: =IF($K34="N",0,IF(IF($C$6="Auction",$H34,$I34)=0,0,ROUNDUP(IF($C$6="Auction",$H34,$I34)*(1+IF($J34="Y",$C$10,0)),0))) -> 5 | M34: B1FS | N34: 0 | O34: =WORKDAY($P$33,1+$N34,Holidays!$B$5:$B$60) -> 46373 | P34: =IF($K34="N",WORKDAY($O34,-1,Holidays!$B$5:$B$60),IF($L34=0,$O34,WORKDAY($O34,$L34-1,Holidays!$B$5:$B$60))) -> 46379 | Q34: Not started | R34: =IF(AND($G34="HOLD",$K34="Y"),"■ HOLD: go/no-go. ","")
A35: B3 | B35: B Pre-start | C35: Sign contract: scope, stage payments, 5% retention; check insurance, verify CIS | D35: Paul | E35: Both | G35: HOLD | H35: 2 | I35: 2 | J35: N | K35: =IF(AND(OR($E35="Both",$E35=$C$6),OR($F35="",IFERROR(INDEX($F$5:$F$13,MATCH($F35,$E$5:$E$13,0)),"Y")="Y")),"Y","N") -> Y | L35: =IF($K35="N",0,IF(IF($C$6="Auction",$H35,$I35)=0,0,ROUNDUP(IF($C$6="Auction",$H35,$I35)*(1+IF($J35="Y",$C$10,0)),0))) -> 2 | M35: B2FS | N35: 0 | O35: =WORKDAY($P$34,1+$N35,Holidays!$B$5:$B$60) -> 46380 | P35: =IF($K35="N",WORKDAY($O35,-1,Holidays!$B$5:$B$60),IF($L35=0,$O35,WORKDAY($O35,$L35-1,Holidays!$B$5:$B$60))) -> 46391 | Q35: Not started | R35: =IF(AND($G35="HOLD",$K35="Y"),"■ HOLD: go/no-go. ","") -> ■ HOLD: go/no-go. | S35: No signed scope + price = no start.
A36: B4 | B36: B Pre-start | C36: Order long-lead items (kitchen, boiler, windows) | D36: Paul / builder | E36: Both | H36: 1 | I36: 1 | J36: N | K36: =IF(AND(OR($E36="Both",$E36=$C$6),OR($F36="",IFERROR(INDEX($F$5:$F$13,MATCH($F36,$E$5:$E$13,0)),"Y")="Y")),"Y","N") -> Y | L36: =IF($K36="N",0,IF(IF($C$6="Auction",$H36,$I36)=0,0,ROUNDUP(IF($C$6="Auction",$H36,$I36)*(1+IF($J36="Y",$C$10,0)),0))) -> 1 | M36: B3FS | N36: 0 | O36: =WORKDAY($P$35,1+$N36,Holidays!$B$5:$B$60) -> 46392 | P36: =IF($K36="N",WORKDAY($O36,-1,Holidays!$B$5:$B$60),IF($L36=0,$O36,WORKDAY($O36,$L36-1,Holidays!$B$5:$B$60))) -> 46392 | Q36: Not started | R36: =IF(AND($G36="HOLD",$K36="Y"),"■ HOLD: go/no-go. ","")
A37: B5 | B37: B Pre-start | C37: Long-lead delivery window | D37: Suppliers | E37: Both | H37: 15 | I37: 15 | J37: N | K37: =IF(AND(OR($E37="Both",$E37=$C$6),OR($F37="",IFERROR(INDEX($F$5:$F$13,MATCH($F37,$E$5:$E$13,0)),"Y")="Y")),"Y","N") -> Y | L37: =IF($K37="N",0,IF(IF($C$6="Auction",$H37,$I37)=0,0,ROUNDUP(IF($C$6="Auction",$H37,$I37)*(1+IF($J37="Y",$C$10,0)),0))) -> 15 | M37: B4FS | N37: 0 | O37: =WORKDAY($P$36,1+$N37,Holidays!$B$5:$B$60) -> 46393 | P37: =IF($K37="N",WORKDAY($O37,-1,Holidays!$B$5:$B$60),IF($L37=0,$O37,WORKDAY($O37,$L37-1,Holidays!$B$5:$B$60))) -> 46413 | Q37: Not started | R37: =IF(AND($G37="HOLD",$K37="Y"),"■ HOLD: go/no-go. ","") | S37: Typical 3 weeks; windows can be 4–6. Edit to supplier quote.
A38: B6 | B38: B Pre-start | C38: Asbestos refurbishment survey | D38: Surveyor | E38: Both | F38: Pre-2000 build | H38: 5 | I38: 5 | J38: N | K38: =IF(AND(OR($E38="Both",$E38=$C$6),OR($F38="",IFERROR(INDEX($F$5:$F$13,MATCH($F38,$E$5:$E$13,0)),"Y")="Y")),"Y","N") -> Y | L38: =IF($K38="N",0,IF(IF($C$6="Auction",$H38,$I38)=0,0,ROUNDUP(IF($C$6="Auction",$H38,$I38)*(1+IF($J38="Y",$C$10,0)),0))) -> 5 | M38: A12FS | N38: 0 | O38: =WORKDAY($P$32,1+$N38,Holidays!$B$5:$B$60) -> 46395 | P38: =IF($K38="N",WORKDAY($O38,-1,Holidays!$B$5:$B$60),IF($L38=0,$O38,WORKDAY($O38,$L38-1,Holidays!$B$5:$B$60))) -> 46401 | Q38: Not started | R38: =IF(AND($G38="HOLD",$K38="Y"),"■ HOLD: go/no-go. ","") | S38: Before any intrusive work on a pre-2000 property (HSE guidance — confirm with contractor).
A39: B7 | B39: B Pre-start | C39: Utilities and meter readings, council tax, change locks, skip, start photos | D39: Paul | E39: Both | H39: 1 | I39: 1 | J39: N | K39: =IF(AND(OR($E39="Both",$E39=$C$6),OR($F39="",IFERROR(INDEX($F$5:$F$13,MATCH($F39,$E$5:$E$13,0)),"Y")="Y")),"Y","N") -> Y | L39: =IF($K39="N",0,IF(IF($C$6="Auction",$H39,$I39)=0,0,ROUNDUP(IF($C$6="Auction",$H39,$I39)*(1+IF($J39="Y",$C$10,0)),0))) -> 1 | M39: A12FS | N39: 0 | O39: =WORKDAY($P$32,1+$N39,Holidays!$B$5:$B$60) -> 46395 | P39: =IF($K39="N",WORKDAY($O39,-1,Holidays!$B$5:$B$60),IF($L39=0,$O39,WORKDAY($O39,$L39-1,Holidays!$B$5:$B$60))) -> 46395 | Q39: Not started | R39: =IF(AND($G39="HOLD",$K39="Y"),"■ HOLD: go/no-go. ","")
A40: C1 | B40: C Strip-out & structure | C40: Strip-out: kitchen, bathroom, flooring, blown plaster | D40: Builder | E40: Both | H40: 4 | I40: 4 | J40: Y | K40: =IF(AND(OR($E40="Both",$E40=$C$6),OR($F40="",IFERROR(INDEX($F$5:$F$13,MATCH($F40,$E$5:$E$13,0)),"Y")="Y")),"Y","N") -> Y | L40: =IF($K40="N",0,IF(IF($C$6="Auction",$H40,$I40)=0,0,ROUNDUP(IF($C$6="Auction",$H40,$I40)*(1+IF($J40="Y",$C$10,0)),0))) -> 5 | M40: B7FS; B6FS; B3FS | N40: 0 | O40: =MAX(WORKDAY($P$39,1+$N40,Holidays!$B$5:$B$60),WORKDAY($P$38,1+$N40,Holidays!$B$5:$B$60),WORKDAY($P$35,1+$N40,Holidays!$B$5:$B$60)) -> 46402 | P40: =IF($K40="N",WORKDAY($O40,-1,Holidays!$B$5:$B$60),IF($L40=0,$O40,WORKDAY($O40,$L40-1,Holidays!$B$5:$B$60))) -> 46408 | Q40: Not started | R40: =IF(AND($G40="HOLD",$K40="Y"),"■ HOLD: go/no-go. ","")
A41: C2 | B41: C Strip-out & structure | C41: Opening-up inspection; update costs in DealsDash | D41: Paul + builder | E41: Both | G41: HOLD | H41: 1 | I41: 1 | J41: N | K41: =IF(AND(OR($E41="Both",$E41=$C$6),OR($F41="",IFERROR(INDEX($F$5:$F$13,MATCH($F41,$E$5:$E$13,0)),"Y")="Y")),"Y","N") -> Y | L41: =IF($K41="N",0,IF(IF($C$6="Auction",$H41,$I41)=0,0,ROUNDUP(IF($C$6="Auction",$H41,$I41)*(1+IF($J41="Y",$C$10,0)),0))) -> 1 | M41: C1FS | N41: 0 | O41: =WORKDAY($P$40,1+$N41,Holidays!$B$5:$B$60) -> 46409 | P41: =IF($K41="N",WORKDAY($O41,-1,Holidays!$B$5:$B$60),IF($L41=0,$O41,WORKDAY($O41,$L41-1,Holidays!$B$5:$B$60))) -> 46409 | Q41: Not started | R41: =IF(AND($G41="HOLD",$K41="Y"),"■ HOLD: go/no-go. ","") -> ■ HOLD: go/no-go. | S41: Hidden defects show here. Re-check profit vs target before committing more spend.
A42: C3 | B42: C Strip-out & structure | C42: Structural works (engineer design + Building Control notice) | D42: Builder / engineer | E42: Both | F42: Structural | H42: 5 | I42: 5 | J42: Y | K42: =IF(AND(OR($E42="Both",$E42=$C$6),OR($F42="",IFERROR(INDEX($F$5:$F$13,MATCH($F42,$E$5:$E$13,0)),"Y")="Y")),"Y","N") -> N | L42: =IF($K42="N",0,IF(IF($C$6="Auction",$H42,$I42)=0,0,ROUNDUP(IF($C$6="Auction",$H42,$I42)*(1+IF($J42="Y",$C$10,0)),0))) -> 0 | M42: C2FS | N42: 0 | O42: =WORKDAY($P$41,1+$N42,Holidays!$B$5:$B$60) -> 46412 | P42: =IF($K42="N",WORKDAY($O42,-1,Holidays!$B$5:$B$60),IF($L42=0,$O42,WORKDAY($O42,$L42-1,Holidays!$B$5:$B$60))) -> 46409 | Q42: Not started | R42: =IF(AND($G42="HOLD",$K42="Y"),"■ HOLD: go/no-go. ","")
A43: C4 | B43: C Strip-out & structure | C43: Damp-proofing / timber treatment | D43: Specialist | E43: Both | F43: Damp/timber | H43: 3 | I43: 3 | J43: Y | K43: =IF(AND(OR($E43="Both",$E43=$C$6),OR($F43="",IFERROR(INDEX($F$5:$F$13,MATCH($F43,$E$5:$E$13,0)),"Y")="Y")),"Y","N") -> Y | L43: =IF($K43="N",0,IF(IF($C$6="Auction",$H43,$I43)=0,0,ROUNDUP(IF($C$6="Auction",$H43,$I43)*(1+IF($J43="Y",$C$10,0)),0))) -> 4 | M43: C2FS | N43: 0 | O43: =WORKDAY($P$41,1+$N43,Holidays!$B$5:$B$60) -> 46412 | P43: =IF($K43="N",WORKDAY($O43,-1,Holidays!$B$5:$B$60),IF($L43=0,$O43,WORKDAY($O43,$L43-1,Holidays!$B$5:$B$60))) -> 46415 | Q43: Not started | R43: =IF(AND($G43="HOLD",$K43="Y"),"■ HOLD: go/no-go. ","") | S43: Get the guarantee for the sale pack.
...

Sheet Deal 2
A1: VIXIV LTD — Flip programme: Deal 2
A2: Edit only the YELLOW cells (blue text). Dates, Gantt and flags recalculate. Durations are working days. Example values shown — replace with your deal.
B4: DEAL INPUTS | E4: SCOPE SWITCHES (Y/N) | H4: KEY DATES (calculated)
B5: Deal name / address | C5: EXAMPLE — 3-bed semi via agent (replace) | E5: Pre-2000 build | F5: Y | H5: Purchase completion | I5: =$P$32 -> 46477
B6: Purchase route | C6: Estate agent | E6: Structural | F6: N | H6: Works start (strip-out) | I6: =$O$40 -> 46485
B7: Deal secured date | C7: 46419 | E7: Damp/timber | F7: Y | H7: Practical completion | I7: =$O$63 -> 46563
B8: Auction completion period (calendar days) | C8: 28 | E8: Roof/external | F8: N | H8: Listed | I8: =$O$67 -> 46568
B9: Agent route: exchange → completion (WD) | C9: 10 | E9: Windows/doors | F9: Y | H9: Sale agreed | I9: =$P$68 -> 46610
B10: Contingency on construction durations | C10: 0.15 | E10: Rewire | F10: Y | H10: Sale completed | I10: =$P$72 -> 46682
B11: Winter drying allowance (extra WD, Nov–Feb) | C11: 3 | E11: Heating/boiler | F11: Y | H11: Build duration (WD) | I11: =NETWORKDAYS($I$6,$I$7,Holidays!$B$5:$B$60) -> 55
B12: WD to agree a sale after listing | C12: 30 | E12: Kitchen | F12: Y | H12: Months owned (completion → sale) | I12: =($I$10-$I$5)/30.44 -> 6.7345598
B13: Bridge term (months) | C13: 12 | E13: Bathroom | F13: Y | H13: Bridge headroom (months) | I13: =$C$13-$I$12 -> 5.2654402
B14: Lead contractor | C14: Friend (general builder) | H14: Deal secured → sale completed (days) | I14: =$I$10-$C$7 -> 263
B15: Sale: exchange → completion (WD) | C15: 10
B17: Gantt key: | C17: A Purchase & DD | D17: B Pre-start | E17: C Strip-out & structure | F17: D First fix | G17: E Plaster | H17: F Second fix & finish | I17: G Sign-off | J17: H Sale & close-out | K17: ■ milestone
U19: =TEXT(U20,"mmm yy") -> Feb 27 | V19: =IF(MONTH(V20)<>MONTH(U20),TEXT(V20,"mmm yy"),"") | W19: =IF(MONTH(W20)<>MONTH(V20),TEXT(W20,"mmm yy"),"") | X19: =IF(MONTH(X20)<>MONTH(W20),TEXT(X20,"mmm yy"),"") | Y19: =IF(MONTH(Y20)<>MONTH(X20),TEXT(Y20,"mmm yy"),"") -> Mar 27 | Z19: =IF(MONTH(Z20)<>MONTH(Y20),TEXT(Z20,"mmm yy"),"") | AA19: =IF(MONTH(AA20)<>MONTH(Z20),TEXT(AA20,"mmm yy"),"") | AB19: =IF(MONTH(AB20)<>MONTH(AA20),TEXT(AB20,"mmm yy"),"") | AC19: =IF(MONTH(AC20)<>MONTH(AB20),TEXT(AC20,"mmm yy"),"") | ... CB19: =IF(MONTH(CB20)<>MONTH(CA20),TEXT(CB20,"mmm yy"),"")
A20: ID | B20: Phase | C20: Activity | D20: Owner | E20: Route | F20: Scope switch | G20: Hold point | H20: Dur WD (auction) | I20: Dur WD (agent) | J20: Contingency? | K20: Applies? | L20: Dur used (WD) | M20: Predecessors | N20: Lag (WD) | O20: Start | P20: Finish | Q20: Status | R20: Flags | S20: Notes / what good looks like | U20: =$O$21-WEEKDAY($O$21,3) -> 46419 | V20: =U20+7 -> 46426 | W20: =V20+7 -> 46433 | X20: =W20+7 -> 46440 | Y20: =X20+7 -> 46447 | Z20: =Y20+7 -> 46454 | AA20: =Z20+7 -> 46461 | AB20: =AA20+7 -> 46468 | AC20: =AB20+7 -> 46475 | ... CB20: =CA20+7 -> 46832
A21: A1 | B21: A Purchase & DD | C21: Deal secured (auction: hammer falls = exchange; agent: offer accepted) | D21: Paul | E21: Both | H21: 0 | I21: 0 | J21: N | K21: =IF(AND(OR($E21="Both",$E21=$C$6),OR($F21="",IFERROR(INDEX($F$5:$F$13,MATCH($F21,$E$5:$E$13,0)),"Y")="Y")),"Y","N") -> Y | L21: =IF($K21="N",0,IF(IF($C$6="Auction",$H21,$I21)=0,0,ROUNDUP(IF($C$6="Auction",$H21,$I21)*(1+IF($J21="Y",$C$10,0)),0))) -> 0 | M21: — | N21: 0 | O21: =WORKDAY($C$7-1,1,Holidays!$B$5:$B$60) -> 46419 | P21: =IF($K21="N",WORKDAY($O21,-1,Holidays!$B$5:$B$60),IF($L21=0,$O21,WORKDAY($O21,$L21-1,Holidays!$B$5:$B$60))) -> 46419 | Q21: Not started | R21: =IF(AND($G21="HOLD",$K21="Y"),"■ HOLD: go/no-go. ","") | S21: Day 0. Everything else is driven from the date in C7.
A22: A2 | B22: A Purchase & DD | C22: Buildings insurance (unoccupied cover) in force | D22: Paul / broker | E22: Both | H22: 1 | I22: 1 | J22: N | K22: =IF(AND(OR($E22="Both",$E22=$C$6),OR($F22="",IFERROR(INDEX($F$5:$F$13,MATCH($F22,$E$5:$E$13,0)),"Y")="Y")),"Y","N") -> Y | L22: =IF($K22="N",0,IF(IF($C$6="Auction",$H22,$I22)=0,0,ROUNDUP(IF($C$6="Auction",$H22,$I22)*(1+IF($J22="Y",$C$10,0)),0))) -> 1 | M22: A1SS | N22: 0 | O22: =WORKDAY($O$21,$N22,Holidays!$B$5:$B$60) -> 46419 | P22: =IF($K22="N",WORKDAY($O22,-1,Holidays!$B$5:$B$60),IF($L22=0,$O22,WORKDAY($O22,$L22-1,Holidays!$B$5:$B$60))) -> 46419 | Q22: Not started | R22: =IF(AND($G22="HOLD",$K22="Y"),"■ HOLD: go/no-go. ","") | S22: Auction: risk passes to you at the hammer. Agent route: must be on cover from exchange at the latest.
A23: A3 | B23: A Purchase & DD | C23: Pay 10% deposit + buyer's premium / auction fees | D23: Paul | E23: Auction | H23: 1 | I23: 0 | J23: N | K23: =IF(AND(OR($E23="Both",$E23=$C$6),OR($F23="",IFERROR(INDEX($F$5:$F$13,MATCH($F23,$E$5:$E$13,0)),"Y")="Y")),"Y","N") -> N | L23: =IF($K23="N",0,IF(IF($C$6="Auction",$H23,$I23)=0,0,ROUNDUP(IF($C$6="Auction",$H23,$I23)*(1+IF($J23="Y",$C$10,0)),0))) -> 0 | M23: A1SS | N23: 0 | O23: =WORKDAY($O$21,$N23,Holidays!$B$5:$B$60) -> 46419 | P23: =IF($K23="N",WORKDAY($O23,-1,Holidays!$B$5:$B$60),IF($L23=0,$O23,WORKDAY($O23,$L23-1,Holidays!$B$5:$B$60))) -> 46416 | Q23: Not started | R23: =IF(AND($G23="HOLD",$K23="Y"),"■ HOLD: go/no-go. ","") | S23: Paid on the day. Funds must be ready before you bid.
A24: A4 | B24: A Purchase & DD | C24: Instruct solicitor; legal pack / memorandum of sale to solicitor and lender | D24: Paul | E24: Both | H24: 2 | I24: 2 | J24: N | K24: =IF(AND(OR($E24="Both",$E24=$C$6),OR($F24="",IFERROR(INDEX($F$5:$F$13,MATCH($F24,$E$5:$E$13,0)),"Y")="Y")),"Y","N") -> Y | L24: =IF($K24="N",0,IF(IF($C$6="Auction",$H24,$I24)=0,0,ROUNDUP(IF($C$6="Auction",$H24,$I24)*(1+IF($J24="Y",$C$10,0)),0))) -> 2 | M24: A1SS | N24: 0 | O24: =WORKDAY($O$21,$N24,Holidays!$B$5:$B$60) -> 46419 | P24: =IF($K24="N",WORKDAY($O24,-1,Holidays!$B$5:$B$60),IF($L24=0,$O24,WORKDAY($O24,$L24-1,Holidays!$B$5:$B$60))) -> 46420 | Q24: Not started | R24: =IF(AND($G24="HOLD",$K24="Y"),"■ HOLD: go/no-go. ","")
A25: A5 | B25: A Purchase & DD | C25: Bridging valuation instructed and inspection done | D25: Broker / lender | E25: Both | H25: 5 | I25: 5 | J25: N | K25: =IF(AND(OR($E25="Both",$E25=$C$6),OR($F25="",IFERROR(INDEX($F$5:$F$13,MATCH($F25,$E$5:$E$13,0)),"Y")="Y")),"Y","N") -> Y | L25: =IF($K25="N",0,IF(IF($C$6="Auction",$H25,$I25)=0,0,ROUNDUP(IF($C$6="Auction",$H25,$I25)*(1+IF($J25="Y",$C$10,0)),0))) -> 5 | M25: A4SS | N25: 1 | O25: =WORKDAY($O$24,$N25,Holidays!$B$5:$B$60) -> 46420 | P25: =IF($K25="N",WORKDAY($O25,-1,Holidays!$B$5:$B$60),IF($L25=0,$O25,WORKDAY($O25,$L25-1,Holidays!$B$5:$B$60))) -> 46426 | Q25: Not started | R25: =IF(AND($G25="HOLD",$K25="Y"),"■ HOLD: go/no-go. ","") | S25: Ideally have a decision in principle BEFORE the auction.
A26: A6 | B26: A Purchase & DD | C26: Bridging underwriting and formal loan offer | D26: Lender | E26: Both | H26: 5 | I26: 5 | J26: N | K26: =IF(AND(OR($E26="Both",$E26=$C$6),OR($F26="",IFERROR(INDEX($F$5:$F$13,MATCH($F26,$E$5:$E$13,0)),"Y")="Y")),"Y","N") -> Y | L26: =IF($K26="N",0,IF(IF($C$6="Auction",$H26,$I26)=0,0,ROUNDUP(IF($C$6="Auction",$H26,$I26)*(1+IF($J26="Y",$C$10,0)),0))) -> 5 | M26: A5FS | N26: 0 | O26: =WORKDAY($P$25,1+$N26,Holidays!$B$5:$B$60) -> 46427 | P26: =IF($K26="N",WORKDAY($O26,-1,Holidays!$B$5:$B$60),IF($L26=0,$O26,WORKDAY($O26,$L26-1,Holidays!$B$5:$B$60))) -> 46433 | Q26: Not started | R26: =IF(AND($G26="HOLD",$K26="Y"),"■ HOLD: go/no-go. ","")
A27: A7 | B27: A Purchase & DD | C27: Searches and enquiries raised and answered | D27: Solicitor | E27: Estate agent | H27: 0 | I27: 25 | J27: N | K27: =IF(AND(OR($E27="Both",$E27=$C$6),OR($F27="",IFERROR(INDEX($F$5:$F$13,MATCH($F27,$E$5:$E$13,0)),"Y")="Y")),"Y","N") -> Y | L27: =IF($K27="N",0,IF(IF($C$6="Auction",$H27,$I27)=0,0,ROUNDUP(IF($C$6="Auction",$H27,$I27)*(1+IF($J27="Y",$C$10,0)),0))) -> 25 | M27: A4FS | N27: 0 | O27: =WORKDAY($P$24,1+$N27,Holidays!$B$5:$B$60) -> 46421 | P27: =IF($K27="N",WORKDAY($O27,-1,Holidays!$B$5:$B$60),IF($L27=0,$O27,WORKDAY($O27,$L27-1,Holidays!$B$5:$B$60))) -> 46455 | Q27: Not started | R27: =IF(AND($G27="HOLD",$K27="Y"),"■ HOLD: go/no-go. ","") | S27: Auction route: done BEFORE bidding (see DD Checklist).
A28: A8 | B28: A Purchase & DD | C28: Independent survey + builder walk-round for quote | D28: Surveyor / builder | E28: Estate agent | H28: 0 | I28: 10 | J28: N | K28: =IF(AND(OR($E28="Both",$E28=$C$6),OR($F28="",IFERROR(INDEX($F$5:$F$13,MATCH($F28,$E$5:$E$13,0)),"Y")="Y")),"Y","N") -> Y | L28: =IF($K28="N",0,IF(IF($C$6="Auction",$H28,$I28)=0,0,ROUNDUP(IF($C$6="Auction",$H28,$I28)*(1+IF($J28="Y",$C$10,0)),0))) -> 10 | M28: A4SS | N28: 2 | O28: =WORKDAY($O$24,$N28,Holidays!$B$5:$B$60) -> 46421 | P28: =IF($K28="N",WORKDAY($O28,-1,Holidays!$B$5:$B$60),IF($L28=0,$O28,WORKDAY($O28,$L28-1,Holidays!$B$5:$B$60))) -> 46434 | Q28: Not started | R28: =IF(AND($G28="HOLD",$K28="Y"),"■ HOLD: go/no-go. ","")
A29: A9 | B29: A Purchase & DD | C29: Review title, searches and survey: renegotiate or withdraw | D29: Paul + mentor | E29: Estate agent | G29: HOLD | H29: 0 | I29: 3 | J29: N | K29: =IF(AND(OR($E29="Both",$E29=$C$6),OR($F29="",IFERROR(INDEX($F$5:$F$13,MATCH($F29,$E$5:$E$13,0)),"Y")="Y")),"Y","N") -> Y | L29: =IF($K29="N",0,IF(IF($C$6="Auction",$H29,$I29)=0,0,ROUNDUP(IF($C$6="Auction",$H29,$I29)*(1+IF($J29="Y",$C$10,0)),0))) -> 3 | M29: A7FS; A8FS | N29: 0 | O29: =MAX(WORKDAY($P$27,1+$N29,Holidays!$B$5:$B$60),WORKDAY($P$28,1+$N29,Holidays!$B$5:$B$60)) -> 46456 | P29: =IF($K29="N",WORKDAY($O29,-1,Holidays!$B$5:$B$60),IF($L29=0,$O29,WORKDAY($O29,$L29-1,Holidays!$B$5:$B$60))) -> 46458 | Q29: Not started | R29: =IF(AND($G29="HOLD",$K29="Y"),"■ HOLD: go/no-go. ","") -> ■ HOLD: go/no-go. | S29: Re-run the DealsDash appraisal with real costs. Walk away if it fails.
A30: A10 | B30: A Purchase & DD | C30: Exchange contracts (deposit paid) | D30: Solicitor | E30: Estate agent | H30: 0 | I30: 0 | J30: N | K30: =IF(AND(OR($E30="Both",$E30=$C$6),OR($F30="",IFERROR(INDEX($F$5:$F$13,MATCH($F30,$E$5:$E$13,0)),"Y")="Y")),"Y","N") -> Y | L30: =IF($K30="N",0,IF(IF($C$6="Auction",$H30,$I30)=0,0,ROUNDUP(IF($C$6="Auction",$H30,$I30)*(1+IF($J30="Y",$C$10,0)),0))) -> 0 | M30: A9FS; A6FS | N30: 0 | O30: =MAX(WORKDAY($P$29,1+$N30,Holidays!$B$5:$B$60),WORKDAY($P$26,1+$N30,Holidays!$B$5:$B$60)) -> 46461 | P30: =IF($K30="N",WORKDAY($O30,-1,Holidays!$B$5:$B$60),IF($L30=0,$O30,WORKDAY($O30,$L30-1,Holidays!$B$5:$B$60))) -> 46461 | Q30: Not started | R30: =IF(AND($G30="HOLD",$K30="Y"),"■ HOLD: go/no-go. ","") | S30: Legally committed from here.
A31: A11 | B31: A Purchase & DD | C31: Lender's legal work, report on title, funds requested | D31: Solicitors | E31: Both | H31: 5 | I31: 5 | J31: N | K31: =IF(AND(OR($E31="Both",$E31=$C$6),OR($F31="",IFERROR(INDEX($F$5:$F$13,MATCH($F31,$E$5:$E$13,0)),"Y")="Y")),"Y","N") -> Y | L31: =IF($K31="N",0,IF(IF($C$6="Auction",$H31,$I31)=0,0,ROUNDUP(IF($C$6="Auction",$H31,$I31)*(1+IF($J31="Y",$C$10,0)),0))) -> 5 | M31: A6FS; A10FS | N31: 0 | O31: =MAX(WORKDAY($P$26,1+$N31,Holidays!$B$5:$B$60),WORKDAY($P$30,1+$N31,Holidays!$B$5:$B$60)) -> 46462 | P31: =IF($K31="N",WORKDAY($O31,-1,Holidays!$B$5:$B$60),IF($L31=0,$O31,WORKDAY($O31,$L31-1,Holidays!$B$5:$B$60))) -> 46468 | Q31: Not started | R31: =IF(AND($G31="HOLD",$K31="Y"),"■ HOLD: go/no-go. ","")
A32: A12 | B32: A Purchase & DD | C32: PURCHASE COMPLETION: keys released | D32: Solicitor | E32: Both | H32: 0 | I32: 0 | J32: N | K32: =IF(AND(OR($E32="Both",$E32=$C$6),OR($F32="",IFERROR(INDEX($F$5:$F$13,MATCH($F32,$E$5:$E$13,0)),"Y")="Y")),"Y","N") -> Y | L32: =IF($K32="N",0,IF(IF($C$6="Auction",$H32,$I32)=0,0,ROUNDUP(IF($C$6="Auction",$H32,$I32)*(1+IF($J32="Y",$C$10,0)),0))) -> 0 | M32: A1 (auction) / A10, A11 (agent) | N32: 0 | O32: =IF($C$6="Auction",WORKDAY($O$21+$C$8-1,1,Holidays!$B$5:$B$60),MAX(WORKDAY($P$30,$C$9,Holidays!$B$5:$B$60),WORKDAY($P$31,1,Holidays!$B$5:$B$60))) -> 46477 | P32: =IF($K32="N",WORKDAY($O32,-1,Holidays!$B$5:$B$60),IF($L32=0,$O32,WORKDAY($O32,$L32-1,Holidays!$B$5:$B$60))) -> 46477 | Q32: Not started | R32: =IF(AND($G32="HOLD",$K32="Y"),"■ HOLD: go/no-go. ","")&IF(AND($C$6="Auction",$P$31>$O32),"⚠ Finance not ready by auction completion: deposit at risk. ","") | S32: Auction: fixed by contract (usually 28 calendar days). Agent: exchange + C9 working days.
A33: B1 | B33: B Pre-start | C33: Builder schedule of works and measured scope | D33: Builder | E33: Both | H33: 3 | I33: 3 | J33: N | K33: =IF(AND(OR($E33="Both",$E33=$C$6),OR($F33="",IFERROR(INDEX($F$5:$F$13,MATCH($F33,$E$5:$E$13,0)),"Y")="Y")),"Y","N") -> Y | L33: =IF($K33="N",0,IF(IF($C$6="Auction",$H33,$I33)=0,0,ROUNDUP(IF($C$6="Auction",$H33,$I33)*(1+IF($J33="Y",$C$10,0)),0))) -> 3 | M33: A1FS; A8FS | N33: 0 | O33: =MAX(WORKDAY($P$21,1+$N33,Holidays!$B$5:$B$60),WORKDAY($P$28,1+$N33,Holidays!$B$5:$B$60)) -> 46435 | P33: =IF($K33="N",WORKDAY($O33,-1,Holidays!$B$5:$B$60),IF($L33=0,$O33,WORKDAY($O33,$L33-1,Holidays!$B$5:$B$60))) -> 46437 | Q33: Not started | R33: =IF(AND($G33="HOLD",$K33="Y"),"■ HOLD: go/no-go. ","") | S33: Auction: arrange access via auctioneer/seller, or use the pre-bid viewing scope.
A34: B2 | B34: B Pre-start | C34: Fixed-price quote(s) received; mentor review | D34: Builder / mentor | E34: Both | H34: 5 | I34: 5 | J34: N | K34: =IF(AND(OR($E34="Both",$E34=$C$6),OR($F34="",IFERROR(INDEX($F$5:$F$13,MATCH($F34,$E$5:$E$13,0)),"Y")="Y")),"Y","N") -> Y | L34: =IF($K34="N",0,IF(IF($C$6="Auction",$H34,$I34)=0,0,ROUNDUP(IF($C$6="Auction",$H34,$I34)*(1+IF($J34="Y",$C$10,0)),0))) -> 5 | M34: B1FS | N34: 0 | O34: =WORKDAY($P$33,1+$N34,Holidays!$B$5:$B$60) -> 46440 | P34: =IF($K34="N",WORKDAY($O34,-1,Holidays!$B$5:$B$60),IF($L34=0,$O34,WORKDAY($O34,$L34-1,Holidays!$B$5:$B$60))) -> 46444 | Q34: Not started | R34: =IF(AND($G34="HOLD",$K34="Y"),"■ HOLD: go/no-go. ","")
A35: B3 | B35: B Pre-start | C35: Sign contract: scope, stage payments, 5% retention; check insurance, verify CIS | D35: Paul | E35: Both | G35: HOLD | H35: 2 | I35: 2 | J35: N | K35: =IF(AND(OR($E35="Both",$E35=$C$6),OR($F35="",IFERROR(INDEX($F$5:$F$13,MATCH($F35,$E$5:$E$13,0)),"Y")="Y")),"Y","N") -> Y | L35: =IF($K35="N",0,IF(IF($C$6="Auction",$H35,$I35)=0,0,ROUNDUP(IF($C$6="Auction",$H35,$I35)*(1+IF($J35="Y",$C$10,0)),0))) -> 2 | M35: B2FS | N35: 0 | O35: =WORKDAY($P$34,1+$N35,Holidays!$B$5:$B$60) -> 46447 | P35: =IF($K35="N",WORKDAY($O35,-1,Holidays!$B$5:$B$60),IF($L35=0,$O35,WORKDAY($O35,$L35-1,Holidays!$B$5:$B$60))) -> 46448 | Q35: Not started | R35: =IF(AND($G35="HOLD",$K35="Y"),"■ HOLD: go/no-go. ","") -> ■ HOLD: go/no-go. | S35: No signed scope + price = no start.
A36: B4 | B36: B Pre-start | C36: Order long-lead items (kitchen, boiler, windows) | D36: Paul / builder | E36: Both | H36: 1 | I36: 1 | J36: N | K36: =IF(AND(OR($E36="Both",$E36=$C$6),OR($F36="",IFERROR(INDEX($F$5:$F$13,MATCH($F36,$E$5:$E$13,0)),"Y")="Y")),"Y","N") -> Y | L36: =IF($K36="N",0,IF(IF($C$6="Auction",$H36,$I36)=0,0,ROUNDUP(IF($C$6="Auction",$H36,$I36)*(1+IF($J36="Y",$C$10,0)),0))) -> 1 | M36: B3FS | N36: 0 | O36: =WORKDAY($P$35,1+$N36,Holidays!$B$5:$B$60) -> 46449 | P36: =IF($K36="N",WORKDAY($O36,-1,Holidays!$B$5:$B$60),IF($L36=0,$O36,WORKDAY($O36,$L36-1,Holidays!$B$5:$B$60))) -> 46449 | Q36: Not started | R36: =IF(AND($G36="HOLD",$K36="Y"),"■ HOLD: go/no-go. ","")
A37: B5 | B37: B Pre-start | C37: Long-lead delivery window | D37: Suppliers | E37: Both | H37: 15 | I37: 15 | J37: N | K37: =IF(AND(OR($E37="Both",$E37=$C$6),OR($F37="",IFERROR(INDEX($F$5:$F$13,MATCH($F37,$E$5:$E$13,0)),"Y")="Y")),"Y","N") -> Y | L37: =IF($K37="N",0,IF(IF($C$6="Auction",$H37,$I37)=0,0,ROUNDUP(IF($C$6="Auction",$H37,$I37)*(1+IF($J37="Y",$C$10,0)),0))) -> 15 | M37: B4FS | N37: 0 | O37: =WORKDAY($P$36,1+$N37,Holidays!$B$5:$B$60) -> 46450 | P37: =IF($K37="N",WORKDAY($O37,-1,Holidays!$B$5:$B$60),IF($L37=0,$O37,WORKDAY($O37,$L37-1,Holidays!$B$5:$B$60))) -> 46470 | Q37: Not started | R37: =IF(AND($G37="HOLD",$K37="Y"),"■ HOLD: go/no-go. ","") | S37: Typical 3 weeks; windows can be 4–6. Edit to supplier quote.
A38: B6 | B38: B Pre-start | C38: Asbestos refurbishment survey | D38: Surveyor | E38: Both | F38: Pre-2000 build | H38: 5 | I38: 5 | J38: N | K38: =IF(AND(OR($E38="Both",$E38=$C$6),OR($F38="",IFERROR(INDEX($F$5:$F$13,MATCH($F38,$E$5:$E$13,0)),"Y")="Y")),"Y","N") -> Y | L38: =IF($K38="N",0,IF(IF($C$6="Auction",$H38,$I38)=0,0,ROUNDUP(IF($C$6="Auction",$H38,$I38)*(1+IF($J38="Y",$C$10,0)),0))) -> 5 | M38: A12FS | N38: 0 | O38: =WORKDAY($P$32,1+$N38,Holidays!$B$5:$B$60) -> 46478 | P38: =IF($K38="N",WORKDAY($O38,-1,Holidays!$B$5:$B$60),IF($L38=0,$O38,WORKDAY($O38,$L38-1,Holidays!$B$5:$B$60))) -> 46484 | Q38: Not started | R38: =IF(AND($G38="HOLD",$K38="Y"),"■ HOLD: go/no-go. ","") | S38: Before any intrusive work on a pre-2000 property (HSE guidance — confirm with contractor).
A39: B7 | B39: B Pre-start | C39: Utilities and meter readings, council tax, change locks, skip, start photos | D39: Paul | E39: Both | H39: 1 | I39: 1 | J39: N | K39: =IF(AND(OR($E39="Both",$E39=$C$6),OR($F39="",IFERROR(INDEX($F$5:$F$13,MATCH($F39,$E$5:$E$13,0)),"Y")="Y")),"Y","N") -> Y | L39: =IF($K39="N",0,IF(IF($C$6="Auction",$H39,$I39)=0,0,ROUNDUP(IF($C$6="Auction",$H39,$I39)*(1+IF($J39="Y",$C$10,0)),0))) -> 1 | M39: A12FS | N39: 0 | O39: =WORKDAY($P$32,1+$N39,Holidays!$B$5:$B$60) -> 46478 | P39: =IF($K39="N",WORKDAY($O39,-1,Holidays!$B$5:$B$60),IF($L39=0,$O39,WORKDAY($O39,$L39-1,Holidays!$B$5:$B$60))) -> 46478 | Q39: Not started | R39: =IF(AND($G39="HOLD",$K39="Y"),"■ HOLD: go/no-go. ","")
A40: C1 | B40: C Strip-out & structure | C40: Strip-out: kitchen, bathroom, flooring, blown plaster | D40: Builder | E40: Both | H40: 4 | I40: 4 | J40: Y | K40: =IF(AND(OR($E40="Both",$E40=$C$6),OR($F40="",IFERROR(INDEX($F$5:$F$13,MATCH($F40,$E$5:$E$13,0)),"Y")="Y")),"Y","N") -> Y | L40: =IF($K40="N",0,IF(IF($C$6="Auction",$H40,$I40)=0,0,ROUNDUP(IF($C$6="Auction",$H40,$I40)*(1+IF($J40="Y",$C$10,0)),0))) -> 5 | M40: B7FS; B6FS; B3FS | N40: 0 | O40: =MAX(WORKDAY($P$39,1+$N40,Holidays!$B$5:$B$60),WORKDAY($P$38,1+$N40,Holidays!$B$5:$B$60),WORKDAY($P$35,1+$N40,Holidays!$B$5:$B$60)) -> 46485 | P40: =IF($K40="N",WORKDAY($O40,-1,Holidays!$B$5:$B$60),IF($L40=0,$O40,WORKDAY($O40,$L40-1,Holidays!$B$5:$B$60))) -> 46491 | Q40: Not started | R40: =IF(AND($G40="HOLD",$K40="Y"),"■ HOLD: go/no-go. ","")
A41: C2 | B41: C Strip-out & structure | C41: Opening-up inspection; update costs in DealsDash | D41: Paul + builder | E41: Both | G41: HOLD | H41: 1 | I41: 1 | J41: N | K41: =IF(AND(OR($E41="Both",$E41=$C$6),OR($F41="",IFERROR(INDEX($F$5:$F$13,MATCH($F41,$E$5:$E$13,0)),"Y")="Y")),"Y","N") -> Y | L41: =IF($K41="N",0,IF(IF($C$6="Auction",$H41,$I41)=0,0,ROUNDUP(IF($C$6="Auction",$H41,$I41)*(1+IF($J41="Y",$C$10,0)),0))) -> 1 | M41: C1FS | N41: 0 | O41: =WORKDAY($P$40,1+$N41,Holidays!$B$5:$B$60) -> 46492 | P41: =IF($K41="N",WORKDAY($O41,-1,Holidays!$B$5:$B$60),IF($L41=0,$O41,WORKDAY($O41,$L41-1,Holidays!$B$5:$B$60))) -> 46492 | Q41: Not started | R41: =IF(AND($G41="HOLD",$K41="Y"),"■ HOLD: go/no-go. ","") -> ■ HOLD: go/no-go. | S41: Hidden defects show here. Re-check profit vs target before committing more spend.
A42: C3 | B42: C Strip-out & structure | C42: Structural works (engineer design + Building Control notice) | D42: Builder / engineer | E42: Both | F42: Structural | H42: 5 | I42: 5 | J42: Y | K42: =IF(AND(OR($E42="Both",$E42=$C$6),OR($F42="",IFERROR(INDEX($F$5:$F$13,MATCH($F42,$E$5:$E$13,0)),"Y")="Y")),"Y","N") -> N | L42: =IF($K42="N",0,IF(IF($C$6="Auction",$H42,$I42)=0,0,ROUNDUP(IF($C$6="Auction",$H42,$I42)*(1+IF($J42="Y",$C$10,0)),0))) -> 0 | M42: C2FS | N42: 0 | O42: =WORKDAY($P$41,1+$N42,Holidays!$B$5:$B$60) -> 46493 | P42: =IF($K42="N",WORKDAY($O42,-1,Holidays!$B$5:$B$60),IF($L42=0,$O42,WORKDAY($O42,$L42-1,Holidays!$B$5:$B$60))) -> 46492 | Q42: Not started | R42: =IF(AND($G42="HOLD",$K42="Y"),"■ HOLD: go/no-go. ","")
A43: C4 | B43: C Strip-out & structure | C43: Damp-proofing / timber treatment | D43: Specialist | E43: Both | F43: Damp/timber | H43: 3 | I43: 3 | J43: Y | K43: =IF(AND(OR($E43="Both",$E43=$C$6),OR($F43="",IFERROR(INDEX($F$5:$F$13,MATCH($F43,$E$5:$E$13,0)),"Y")="Y")),"Y","N") -> Y | L43: =IF($K43="N",0,IF(IF($C$6="Auction",$H43,$I43)=0,0,ROUNDUP(IF($C$6="Auction",$H43,$I43)*(1+IF($J43="Y",$C$10,0)),0))) -> 4 | M43: C2FS | N43: 0 | O43: =WORKDAY($P$41,1+$N43,Holidays!$B$5:$B$60) -> 46493 | P43: =IF($K43="N",WORKDAY($O43,-1,Holidays!$B$5:$B$60),IF($L43=0,$O43,WORKDAY($O43,$L43-1,Holidays!$B$5:$B$60))) -> 46498 | Q43: Not started | R43: =IF(AND($G43="HOLD",$K43="Y"),"■ HOLD: go/no-go. ","") | S43: Get the guarantee for the sale pack.
...

Sheet Holidays
A1: Non-working days used by every date formula
A2: England & Wales bank holidays computed for 2026–2028 — verify at gov.uk/bank-holidays. Trade shutdown days are editable; add your own (e.g. crew holidays) in the yellow rows.
A4: Description | B4: Date
A5: Christmas / Boxing Day (substitute if weekend) | B5: 46381
A6: Christmas / Boxing Day (substitute if weekend) | B6: 46384
A7: Trade Christmas shutdown (editable) | B7: 46385
A8: Trade Christmas shutdown (editable) | B8: 46386
A9: Trade Christmas shutdown (editable) | B9: 46387
A10: New Year's Day | B10: 46388
A11: Good Friday | B11: 46472
A12: Easter Monday | B12: 46475
A13: Early May bank holiday | B13: 46510
A14: Spring bank holiday | B14: 46538
A15: Summer bank holiday | B15: 46629
A16: Christmas / Boxing Day (substitute if weekend) | B16: 46748
... A28: Christmas / Boxing Day (substitute if weekend) | B28: 47113
